Workbook

Sheet NVA. EST. PROGRAMATICA 2026
A1: DG | B1: ÁREA ADMINISTRATIVA | C1: Fin | D1: FN | E1: SF | F1: PG | G1: SP | H1: Py | I1: DG | K1: D Aux | P1: Denominación de Programa | Q1: Denominación de Proyecto | R1: Descripción de Acciones | S1: Tipo de Indicador | T1: Unidad de Medida
A2: D00 | B2: SECRETARÍA DEL AYUNTAMIENTO | C2: 01 | D2: 03 | E2: 09 | F2: 02 | G2: 01 | H2: 01 | I2: D00 | K2: 155 | L2: =VLOOKUP(K2,'GACETA 3'!E2:$F$75,2,0) -> Área Jurídica | M2: =CONCATENATE(C2,D2,E2,F2,G2) -> 0103090201 | N2: =VLOOKUP(M2,GACETA!$A$1:$C$186,3,0) -> M | O2: =VLOOKUP(M2,GACETA!$A$1:$C$186,2,0) -> Revisión y emisión de la reglamentación municipal | P2: Reglamentación municipal | Q2: Revisión y emisión de la reglamentación municipal | R2: Reglamentos y disposiciones de observancia general en el municipio publicadas | S2: Gestión | T2: Gaceta
C3: 01 | D3: 03 | E3: 09 | F3: 02 | G3: 01 | H3: 01 | I3: D00 | K3: 155 | L3: =VLOOKUP(K3,'GACETA 3'!E3:$F$75,2,0) -> Área Jurídica | M3: =CONCATENATE(C3,D3,E3,F3,G3) -> 0103090201 | N3: =VLOOKUP(M3,GACETA!$A$1:$C$186,3,0) -> M | O3: =VLOOKUP(M3,GACETA!$A$1:$C$186,2,0) -> Revisión y emisión de la reglamentación municipal | R3: Capacitaciones en materia reglamentaria otorgadas | S3: Gestión | T3: Capacitación
C4: 01 | D4: 03 | E4: 09 | F4: 02 | G4: 01 | H4: 01 | I4: D00 | K4: 155 | L4: =VLOOKUP(K4,'GACETA 3'!E4:$F$75,2,0) -> Área Jurídica | M4: =CONCATENATE(C4,D4,E4,F4,G4) -> 0103090201 | N4: =VLOOKUP(M4,GACETA!$A$1:$C$186,3,0) -> M | O4: =VLOOKUP(M4,GACETA!$A$1:$C$186,2,0) -> Revisión y emisión de la reglamentación municipal | R4: Revisión de propuestas viables de modificación a Leyes, decretos y reglamentos municipales | S4: Gestión | T4: Propuesta
C5: 01 | D5: 03 | E5: 09 | F5: 02 | G5: 01 | H5: 01 | I5: D00 | K5: 155 | L5: =VLOOKUP(K5,'GACETA 3'!E5:$F$75,2,0) -> Área Jurídica | M5: =CONCATENATE(C5,D5,E5,F5,G5) -> 0103090201 | N5: =VLOOKUP(M5,GACETA!$A$1:$C$186,3,0) -> M | O5: =VLOOKUP(M5,GACETA!$A$1:$C$186,2,0) -> Revisión y emisión de la reglamentación municipal | R5: Realización de sesiones de cabildo | S5: Gestión | T5: Sesión
C6: 01 | D6: 05 | E6: 02 | F6: 06 | G6: 06 | I6: D00 | K6: 114 | L6: =VLOOKUP(K6,'GACETA 3'!E6:$F$75,2,0) -> Control Patrimonial | M6: =CONCATENATE(C6,D6,E6,F6,G6) -> 0105020606 | N6: =VLOOKUP(M6,GACETA!$A$1:$C$186,3,0) -> M | O6: =VLOOKUP(M6,GACETA!$A$1:$C$186,2,0) -> Control del patrimonio y normatividad | P6: Consolidación de la administración pública de resultados | Q6: Control del patrimonio y normatividad | R6: Realizar los levantamientos fisicos de los bienes muebles e inmuebles. | S6: Gestión | T6: Bien
C7: 01 | D7: 05 | E7: 02 | F7: 06 | G7: 06 | I7: D00 | K7: 114 | L7: =VLOOKUP(K7,'GACETA 3'!E7:$F$75,2,0) -> Control Patrimonial | M7: =CONCATENATE(C7,D7,E7,F7,G7) -> 0105020606 | N7: =VLOOKUP(M7,GACETA!$A$1:$C$186,3,0) -> M | O7: =VLOOKUP(M7,GACETA!$A$1:$C$186,2,0) -> Control del patrimonio y normatividad | R7: Actualizar el inventario mediante revisiones fisicas por areas de trabajo de la Administracion Publica Municipal. | S7: Gestión | T7: Revision fisica
C8: 01 | D8: 05 | E8: 02 | F8: 06 | G8: 06 | I8: D00 | K8: 114 | L8: =VLOOKUP(K8,'GACETA 3'!E8:$F$75,2,0) -> Control Patrimonial | M8: =CONCATENATE(C8,D8,E8,F8,G8) -> 0105020606 | N8: =VLOOKUP(M8,GACETA!$A$1:$C$186,3,0) -> M | O8: =VLOOKUP(M8,GACETA!$A$1:$C$186,2,0) -> Control del patrimonio y normatividad | R8: Actualización de registros de bienes inmuebles propiedad municipal | S8: Gestión | T8: Registros actualizados
C9: 01 | D9: 03 | E9: 09 | F9: 03 | G9: 01 | I9: D00 | K9: 108 | L9: =VLOOKUP(K9,'GACETA 3'!$E$9:$F$75,2,0) -> Juzgados Cívicos | M9: =CONCATENATE(C9,D9,E9,F9,G9) -> 0103090301 | N9: =VLOOKUP(M9,GACETA!$A$1:$C$186,3,0) -> L | O9: =VLOOKUP(M9,GACETA!$A$1:$C$186,2,0) -> Mediación, conciliación y función calificadora municipal | P9: Justicia Cívica Municipal | Q9: Mediación, conciliación y función calificadora municipal | R9: Garantizar la paz social, convivencia familiar y vecinal a través de medios alternativos de solucion de controversias. | S9: Gestión | T9: Mediacion
C10: 01 | D10: 03 | E10: 09 | F10: 03 | G10: 01 | I10: D00 | K10: 108 | L10: =VLOOKUP(K10,'GACETA 3'!$E$9:$F$75,2,0) -> Juzgados Cívicos | M10: =CONCATENATE(C10,D10,E10,F10,G10) -> 0103090301 | N10: =VLOOKUP(M10,GACETA!$A$1:$C$186,3,0) -> L | O10: =VLOOKUP(M10,GACETA!$A$1:$C$186,2,0) -> Mediación, conciliación y función calificadora municipal | R10: Citar a las partes en conflicto con la finalidad de dirimir sus diferencias a través del dialogo y medios alternativos de solución | S10: Gestión | T10: Citatorio
C11: 01 | D11: 03 | E11: 09 | F11: 03 | G11: 01 | I11: D00 | K11: 108 | L11: =VLOOKUP(K11,'GACETA 3'!$E$9:$F$75,2,0) -> Juzgados Cívicos | M11: =CONCATENATE(C11,D11,E11,F11,G11) -> 0103090301 | N11: =VLOOKUP(M11,GACETA!$A$1:$C$186,3,0) -> L | O11: =VLOOKUP(M11,GACETA!$A$1:$C$186,2,0) -> Mediación, conciliación y función calificadora municipal | R11: Dar cumplimiento a los ordenamientos legales a través de la aplicación de sanciones por infracciones | S11: Gestión | T11: Sanción
C12: 01 | D12: 03 | E12: 09 | F12: 03 | G12: 01 | I12: D00 | K12: 108 | L12: =VLOOKUP(K12,'GACETA 3'!$E$9:$F$75,2,0) -> Juzgados Cívicos | M12: =CONCATENATE(C12,D12,E12,F12,G12) -> 0103090301 | N12: =VLOOKUP(M12,GACETA!$A$1:$C$186,3,0) -> L | O12: =VLOOKUP(M12,GACETA!$A$1:$C$186,2,0) -> Mediación, conciliación y función calificadora municipal | R12: Capacitaciones en tematicas relacionadas a la Justicia Civica | S12: Gestión | T12: Capacitación
C13: 01 | D13: 03 | E13: 09 | F13: 03 | G13: 01 | I13: D00 | K13: 108 | L13: =VLOOKUP(K13,'GACETA 3'!$E$9:$F$75,2,0) -> Juzgados Cívicos | M13: =CONCATENATE(C13,D13,E13,F13,G13) -> 0103090301 | N13: =VLOOKUP(M13,GACETA!$A$1:$C$186,3,0) -> L | O13: =VLOOKUP(M13,GACETA!$A$1:$C$186,2,0) -> Mediación, conciliación y función calificadora municipal | R13: Difusión de la cultura civica y cultura de la legalidad en medios de comunicación | S13: Gestión | T13: Post
C14: 01 | D14: 03 | E14: 09 | F14: 03 | G14: 01 | I14: D00 | K14: 108 | L14: =VLOOKUP(K14,'GACETA 3'!$E$9:$F$75,2,0) -> Juzgados Cívicos | M14: =CONCATENATE(C14,D14,E14,F14,G14) -> 0103090301 | N14: =VLOOKUP(M14,GACETA!$A$1:$C$186,3,0) -> L | O14: =VLOOKUP(M14,GACETA!$A$1:$C$186,2,0) -> Mediación, conciliación y función calificadora municipal | R14: Informes de Resultados de las Acciones del Juzgado Cívico | S14: Gestión | T14: Informe
C15: 01 | D15: 03 | E15: 09 | F15: 03 | G15: 01 | I15: D00 | K15: 108 | L15: =VLOOKUP(K15,'GACETA 3'!$E$9:$F$75,2,0) -> Juzgados Cívicos | M15: =CONCATENATE(C15,D15,E15,F15,G15) -> 0103090301 | N15: =VLOOKUP(M15,GACETA!$A$1:$C$186,3,0) -> L | O15: =VLOOKUP(M15,GACETA!$A$1:$C$186,2,0) -> Mediación, conciliación y función calificadora municipal | R15: Jornadas de Trabajo en favor de la comunidad | S15: Gestión | T15: Jornada
C16: 01 | D16: 03 | E16: 09 | F16: 03 | G16: 01 | I16: D00 | K16: 108 | L16: =VLOOKUP(K16,'GACETA 3'!$E$9:$F$75,2,0) -> Juzgados Cívicos | M16: =CONCATENATE(C16,D16,E16,F16,G16) -> 0103090301 | N16: =VLOOKUP(M16,GACETA!$A$1:$C$186,3,0) -> L | O16: =VLOOKUP(M16,GACETA!$A$1:$C$186,2,0) -> Mediación, conciliación y función calificadora municipal | R16: Proporcionar asesorias psicologicas y preventivas escolares, enfocado a pdres y adolecentes | S16: Gestión | T16: Asesorías
C17: 01 | D17: 03 | E17: 09 | F17: 03 | G17: 01 | I17: D00 | K17: 108 | L17: =VLOOKUP(K17,'GACETA 3'!$E$9:$F$75,2,0) -> Juzgados Cívicos | M17: =CONCATENATE(C17,D17,E17,F17,G17) -> 0103090301 | N17: =VLOOKUP(M17,GACETA!$A$1:$C$186,3,0) -> L | O17: =VLOOKUP(M17,GACETA!$A$1:$C$186,2,0) -> Mediación, conciliación y función calificadora municipal | R17: Realizar talleres para jovenes menores infractores para su readapatcion | S17: Gestión | T17: Taller
C18: 01 | D18: 08 | E18: 01 | F18: 01 | G18: 02 | I18: D00 | K18: 109 | L18: =VLOOKUP(K18,'GACETA 3'!$E$9:$F$75,2,0) -> Registro Civil | M18: =CONCATENATE(C18,D18,E18,F18,G18) -> 0108010102 | N18: =VLOOKUP(M18,GACETA!$A$1:$C$186,3,0) -> E | O18: =VLOOKUP(M18,GACETA!$A$1:$C$186,2,0) -> Actualización y operación del registro civil | P18: Protección Jurídica de las Personas | Q18: Actualizacion y operación del Registro Civil | R18: Emitir copias certificadas de actas en las Oficialías del registro civil aporvechando el uso de las tecnologías | S18: Gestión | T18: Copia
C19: 01 | D19: 08 | E19: 01 | F19: 01 | G19: 02 | I19: D00 | K19: 109 | L19: =VLOOKUP(K19,'GACETA 3'!$E$9:$F$75,2,0) -> Registro Civil | M19: =CONCATENATE(C19,D19,E19,F19,G19) -> 0108010102 | N19: =VLOOKUP(M19,GACETA!$A$1:$C$186,3,0) -> E | O19: =VLOOKUP(M19,GACETA!$A$1:$C$186,2,0) -> Actualización y operación del registro civil | R19: Proporcionar las constancias de no registro de una forma más ágil a los solicitantes | S19: Gestión | T19: Constancia
C20: 01 | D20: 08 | E20: 01 | F20: 01 | G20: 02 | I20: D00 | K20: 109 | L20: =VLOOKUP(K20,'GACETA 3'!$E$9:$F$75,2,0) -> Registro Civil | M20: =CONCATENATE(C20,D20,E20,F20,G20) -> 0108010102 | N20: =VLOOKUP(M20,GACETA!$A$1:$C$186,3,0) -> E | O20: =VLOOKUP(M20,GACETA!$A$1:$C$186,2,0) -> Actualización y operación del registro civil | R20: Supervisiones a las oficialías del Registro Civil | S20: Gestión | T20: Supervisión
C21: 01 | D21: 08 | E21: 01 | F21: 01 | G21: 02 | I21: D00 | K21: 109 | L21: =VLOOKUP(K21,'GACETA 3'!$E$9:$F$75,2,0) -> Registro Civil | M21: =CONCATENATE(C21,D21,E21,F21,G21) -> 0108010102 | N21: =VLOOKUP(M21,GACETA!$A$1:$C$186,3,0) -> E | O21: =VLOOKUP(M21,GACETA!$A$1:$C$186,2,0) -> Actualización y operación del registro civil | R21: Evaluar el número de parejas que regularizan su estado civil mediante campañas de matrimonios masivos | S21: Gestión | T21: Campaña
C22: 01 | D22: 08 | E22: 01 | F22: 01 | G22: 02 | I22: D00 | K22: 109 | L22: =VLOOKUP(K22,'GACETA 3'!$E$9:$F$75,2,0) -> Registro Civil | M22: =CONCATENATE(C22,D22,E22,F22,G22) -> 0108010102 | N22: =VLOOKUP(M22,GACETA!$A$1:$C$186,3,0) -> E | O22: =VLOOKUP(M22,GACETA!$A$1:$C$186,2,0) -> Actualización y operación del registro civil | R22: Incrementar el número de personas que regularicen su estatus jurídico y personalidad, mediante campañas de registros extemporáneos | S22: Gestión | T22: Registro
C23: 01 | D23: 08 | E23: 01 | F23: 01 | G23: 02 | I23: D00 | K23: 109 | L23: =VLOOKUP(K23,'GACETA 3'!$E$9:$F$75,2,0) -> Registro Civil | M23: =CONCATENATE(C23,D23,E23,F23,G23) -> 0108010102 | N23: =VLOOKUP(M23,GACETA!$A$1:$C$186,3,0) -> E | O23: =VLOOKUP(M23,GACETA!$A$1:$C$186,2,0) -> Actualización y operación del registro civil | R23: Jornadas ciudadanas (matrimonios, registro de nacimientos, expedición de copias, reclusorios) | S23: Gestión | T23: Jornada
A24: B01 | B24: Sindicatura I | C24: 02 | D24: 02 | E24: 02 | F24: 01 | G24: 02 | I24: B01 | K24: 110 | L24: =VLOOKUP(K24,'GACETA 3'!$E$9:$F$75,2,0) -> Acción Cívica | M24: =CONCATENATE(C24,D24,E24,F24,G24) -> 0202020102 | N24: =VLOOKUP(M24,GACETA!$A$1:$C$186,3,0) -> M | O24: =VLOOKUP(M24,GACETA!$A$1:$C$186,2,0) -> Apoyo Solidario | P24: Desarrollo comunitario | Q24: Apoyo solidario | R24: Realizar acciones, obras y apoyos en comunidades por medio de atención a la ciudadanía | S24: Gestión | T24: Solicitudes
C25: 02 | D25: 02 | E25: 02 | F25: 01 | G25: 02 | I25: B02 | K25: 110 | L25: =VLOOKUP(K25,'GACETA 3'!$E$9:$F$75,2,0) -> Acción Cívica | M25: =CONCATENATE(C25,D25,E25,F25,G25) -> 0202020102 | N25: =VLOOKUP(M25,GACETA!$A$1:$C$186,3,0) -> M | O25: =VLOOKUP(M25,GACETA!$A$1:$C$186,2,0) -> Apoyo Solidario | R25: Llevar acabo Sesiones de cabildo para abordar temas en benificio de la poblacion | S25: Gestión | T25: Asistencia
C26: 02 | D26: 02 | E26: 02 | F26: 01 | G26: 02 | I26: B01 | K26: 110 | L26: =VLOOKUP(K26,'GACETA 3'!$E$9:$F$75,2,0) -> Acción Cívica | M26: =CONCATENATE(C26,D26,E26,F26,G26) -> 0202020102 | N26: =VLOOKUP(M26,GACETA!$A$1:$C$186,3,0) -> M | O26: =VLOOKUP(M26,GACETA!$A$1:$C$186,2,0) -> Apoyo Solidario | R26: Realizar sesiones coadyuvando con las áreas administrativas municipales en encomineda establecida bajo comité | S26: Gestión | T26: Sesiones
A27: B02 | B27: Sindicatura II | C27: 02 | D27: 02 | E27: 02 | F27: 01 | G27: 02 | I27: B02 | K27: 110 | L27: =VLOOKUP(K27,'GACETA 3'!$E$9:$F$75,2,0) -> Acción Cívica | M27: =CONCATENATE(C27,D27,E27,F27,G27) -> 0202020102 | N27: =VLOOKUP(M27,GACETA!$A$1:$C$186,3,0) -> M | O27: =VLOOKUP(M27,GACETA!$A$1:$C$186,2,0) -> Apoyo Solidario | P27: Desarrollo comunitario | Q27: Apoyo solidario | R27: Realizar acciones, obras y apoyos en comunidades por medio de atención a la ciudadanía | S27: Gestión | T27: Solicitudes
C28: 02 | D28: 02 | E28: 02 | F28: 01 | G28: 02 | I28: B02 | K28: 110 | L28: =VLOOKUP(K28,'GACETA 3'!$E$9:$F$75,2,0) -> Acción Cívica | M28: =CONCATENATE(C28,D28,E28,F28,G28) -> 0202020102 | N28: =VLOOKUP(M28,GACETA!$A$1:$C$186,3,0) -> M | O28: =VLOOKUP(M28,GACETA!$A$1:$C$186,2,0) -> Apoyo Solidario | R28: Llevar acabo Sesiones de cabildo para abordar temas en benificio de la poblacion | S28: Gestión | T28: Asistencia
C29: 02 | D29: 02 | E29: 02 | F29: 01 | G29: 02 | I29: B02 | K29: 110 | L29: =VLOOKUP(K29,'GACETA 3'!$E$9:$F$75,2,0) -> Acción Cívica | M29: =CONCATENATE(C29,D29,E29,F29,G29) -> 0202020102 | N29: =VLOOKUP(M29,GACETA!$A$1:$C$186,3,0) -> M | O29: =VLOOKUP(M29,GACETA!$A$1:$C$186,2,0) -> Apoyo Solidario | R29: Realizar sesiones coadyuvando con las áreas administrativas municipales en encomineda establecida bajo comité | S29: Gestión | T29: Sesiones
A30: C01 | B30: REGIDURÍA I | C30: 02 | D30: 02 | E30: 02 | F30: 01 | G30: 02 | I30: C01 | K30: 110 | L30: =VLOOKUP(K30,'GACETA 3'!$E$9:$F$75,2,0) -> Acción Cívica | M30: =CONCATENATE(C30,D30,E30,F30,G30) -> 0202020102 | N30: =VLOOKUP(M30,GACETA!$A$1:$C$186,3,0) -> M | O30: =VLOOKUP(M30,GACETA!$A$1:$C$186,2,0) -> Apoyo Solidario | P30: Desarrollo comunitario | Q30: Apoyo solidario | R30: Realizar acciones, obras y apoyos en comunidades por medio de atención a la ciudadanía | S30: Gestión | T30: Solicitudes
C31: 02 | D31: 02 | E31: 02 | F31: 01 | G31: 02 | I31: B02 | K31: 110 | L31: =VLOOKUP(K31,'GACETA 3'!$E$9:$F$75,2,0) -> Acción Cívica | M31: =CONCATENATE(C31,D31,E31,F31,G31) -> 0202020102 | N31: =VLOOKUP(M31,GACETA!$A$1:$C$186,3,0) -> M | O31: =VLOOKUP(M31,GACETA!$A$1:$C$186,2,0) -> Apoyo Solidario | R31: Llevar acabo Sesiones de cabildo para abordar temas en benificio de la poblacion | S31: Gestión | T31: Asistencia
C32: 02 | D32: 02 | E32: 02 | F32: 01 | G32: 02 | I32: C01 | K32: 110 | L32: =VLOOKUP(K32,'GACETA 3'!$E$9:$F$75,2,0) -> Acción Cívica | M32: =CONCATENATE(C32,D32,E32,F32,G32) -> 0202020102 | N32: =VLOOKUP(M32,GACETA!$A$1:$C$186,3,0) -> M | O32: =VLOOKUP(M32,GACETA!$A$1:$C$186,2,0) -> Apoyo Solidario | R32: Realizar sesiones coadyuvando con las áreas administrativas municipales en encomineda establecida bajo comité | S32: Gestión | T32: Sesiones
A33: C02 | B33: REGIDURÍA II | C33: 02 | D33: 02 | E33: 02 | F33: 01 | G33: 02 | I33: C02 | K33: 110 | L33: =VLOOKUP(K33,'GACETA 3'!$E$9:$F$75,2,0) -> Acción Cívica | M33: =CONCATENATE(C33,D33,E33,F33,G33) -> 0202020102 | N33: =VLOOKUP(M33,GACETA!$A$1:$C$186,3,0) -> M | O33: =VLOOKUP(M33,GACETA!$A$1:$C$186,2,0) -> Apoyo Solidario | P33: Desarrollo comunitario | Q33: Apoyo solidario | R33: Realizar acciones, obras y apoyos en comunidades por medio de atención a la ciudadanía | S33: Gestión | T33: Solicitudes
C34: 02 | D34: 02 | E34: 02 | F34: 01 | G34: 02 | I34: B02 | K34: 110 | L34: =VLOOKUP(K34,'GACETA 3'!$E$9:$F$75,2,0) -> Acción Cívica | M34: =CONCATENATE(C34,D34,E34,F34,G34) -> 0202020102 | N34: =VLOOKUP(M34,GACETA!$A$1:$C$186,3,0) -> M | O34: =VLOOKUP(M34,GACETA!$A$1:$C$186,2,0) -> Apoyo Solidario | R34: Llevar acabo Sesiones de cabildo para abordar temas en benificio de la poblacion | S34: Gestión | T34: Asistencia
C35: 02 | D35: 02 | E35: 02 | F35: 01 | G35: 02 | I35: C02 | K35: 110 | L35: =VLOOKUP(K35,'GACETA 3'!$E$9:$F$75,2,0) -> Acción Cívica | M35: =CONCATENATE(C35,D35,E35,F35,G35) -> 0202020102 | N35: =VLOOKUP(M35,GACETA!$A$1:$C$186,3,0) -> M | O35: =VLOOKUP(M35,GACETA!$A$1:$C$186,2,0) -> Apoyo Solidario | R35: Realizar sesiones coadyuvando con las áreas administrativas municipales en encomineda establecida bajo comité | S35: Gestión | T35: Sesiones
A36: C03 | B36: REGIDURÍA III | C36: 02 | D36: 02 | E36: 02 | F36: 01 | G36: 02 | I36: C03 | K36: 110 | L36: =VLOOKUP(K36,'GACETA 3'!$E$9:$F$75,2,0) -> Acción Cívica | M36: =CONCATENATE(C36,D36,E36,F36,G36) -> 0202020102 | N36: =VLOOKUP(M36,GACETA!$A$1:$C$186,3,0) -> M | O36: =VLOOKUP(M36,GACETA!$A$1:$C$186,2,0) -> Apoyo Solidario | P36: Desarrollo comunitario | Q36: Apoyo solidario | R36: Realizar acciones, obras y apoyos en comunidades por medio de atención a la ciudadanía | S36: Gestión | T36: Solicitudes
C37: 02 | D37: 02 | E37: 02 | F37: 01 | G37: 02 | I37: B02 | K37: 110 | L37: =VLOOKUP(K37,'GACETA 3'!$E$9:$F$75,2,0) -> Acción Cívica | M37: =CONCATENATE(C37,D37,E37,F37,G37) -> 0202020102 | N37: =VLOOKUP(M37,GACETA!$A$1:$C$186,3,0) -> M | O37: =VLOOKUP(M37,GACETA!$A$1:$C$186,2,0) -> Apoyo Solidario | R37: Llevar acabo Sesiones de cabildo para abordar temas en benificio de la poblacion | S37: Gestión | T37: Asistencia
C38: 02 | D38: 02 | E38: 02 | F38: 01 | G38: 02 | I38: C03 | K38: 110 | L38: =VLOOKUP(K38,'GACETA 3'!$E$9:$F$75,2,0) -> Acción Cívica | M38: =CONCATENATE(C38,D38,E38,F38,G38) -> 0202020102 | N38: =VLOOKUP(M38,GACETA!$A$1:$C$186,3,0) -> M | O38: =VLOOKUP(M38,GACETA!$A$1:$C$186,2,0) -> Apoyo Solidario | R38: Realizar sesiones coadyuvando con las áreas administrativas municipales en encomineda establecida bajo comité | S38: Gestión | T38: Sesiones
A39: C04 | B39: REGIDURÍA IV | C39: 02 | D39: 02 | E39: 02 | F39: 01 | G39: 02 | I39: C04 | K39: 110 | L39: =VLOOKUP(K39,'GACETA 3'!$E$9:$F$75,2,0) -> Acción Cívica | M39: =CONCATENATE(C39,D39,E39,F39,G39) -> 0202020102 | N39: =VLOOKUP(M39,GACETA!$A$1:$C$186,3,0) -> M | O39: =VLOOKUP(M39,GACETA!$A$1:$C$186,2,0) -> Apoyo Solidario | P39: Desarrollo comunitario | Q39: Apoyo solidario | R39: Realizar acciones, obras y apoyos en comunidades por medio de atención a la ciudadanía | S39: Gestión | T39: Solicitudes
C40: 02 | D40: 02 | E40: 02 | F40: 01 | G40: 02 | I40: B02 | K40: 110 | L40: =VLOOKUP(K40,'GACETA 3'!$E$9:$F$75,2,0) -> Acción Cívica | M40: =CONCATENATE(C40,D40,E40,F40,G40) -> 0202020102 | N40: =VLOOKUP(M40,GACETA!$A$1:$C$186,3,0) -> M | O40: =VLOOKUP(M40,GACETA!$A$1:$C$186,2,0) -> Apoyo Solidario | R40: Llevar acabo Sesiones de cabildo para abordar temas en benificio de la poblacion | S40: Gestión | T40: Asistencia
...

Sheet Hoja2
A2: D00 | B2: SECRETARÍA DEL AYUNTAMIENTO | C2: 155 | D2: Área Jurídica | E2: 0103090201 | F2: =VLOOKUP(E2,GACETA!$A$1:$C$186,3,0) -> M | G2: Revisión y emisión de la reglamentación municipal | I2: Reglamentos y disposiciones de observancia general en el municipio publicadas
A3: D00 | B3: SECRETARÍA DEL AYUNTAMIENTO | C3: 155 | D3: Área Jurídica | E3: 0103090201 | F3: =VLOOKUP(E3,GACETA!$A$1:$C$186,3,0) -> M | G3: Revisión y emisión de la reglamentación municipal | I3: Capacitaciones en materia reglamentaria otorgadas
A4: D00 | B4: SECRETARÍA DEL AYUNTAMIENTO | C4: 155 | D4: Área Jurídica | E4: 0103090201 | F4: =VLOOKUP(E4,GACETA!$A$1:$C$186,3,0) -> M | G4: Revisión y emisión de la reglamentación municipal | I4: Revisión de propuestas viables de modificación a Leyes, decretos y reglamentos municipales
A5: D00 | B5: SECRETARÍA DEL AYUNTAMIENTO | C5: 155 | D5: Área Jurídica | E5: 0103090201 | F5: =VLOOKUP(E5,GACETA!$A$1:$C$186,3,0) -> M | G5: Revisión y emisión de la reglamentación municipal | I5: Realización de sesiones de cabildo
A6: D00 | B6: SECRETARÍA DEL AYUNTAMIENTO | C6: 114 | D6: Control Patrimonial | E6: 0105020606 | F6: =VLOOKUP(E6,GACETA!$A$1:$C$186,3,0) -> M | G6: Control del patrimonio y normatividad | H6: =CONCATENATE(A6," ",C6," ",E6," ",F6) -> D00 114 0105020606 M | I6: Realizar los levantamientos fisicos de los bienes muebles e inmuebles.
A7: D00 | B7: SECRETARÍA DEL AYUNTAMIENTO | C7: 114 | D7: Control Patrimonial | E7: 0105020606 | F7: =VLOOKUP(E7,GACETA!$A$1:$C$186,3,0) -> M | G7: Control del patrimonio y normatividad | H7: =CONCATENATE(A7," ",C7," ",E7," ",F7) -> D00 114 0105020606 M | I7: Actualizar el inventario mediante revisiones fisicas por areas de trabajo de la Administracion Publica Municipal.
A8: D00 | B8: SECRETARÍA DEL AYUNTAMIENTO | C8: 114 | D8: Control Patrimonial | E8: 0105020606 | F8: =VLOOKUP(E8,GACETA!$A$1:$C$186,3,0) -> M | G8: Control del patrimonio y normatividad | H8: =CONCATENATE(A8," ",C8," ",E8," ",F8) -> D00 114 0105020606 M | I8: Actualización de registros de bienes inmuebles propiedad municipal
A9: D00 | B9: SECRETARÍA DEL AYUNTAMIENTO | C9: 108 | D9: Juzgados Cívicos | E9: 0103090301 | F9: =VLOOKUP(E9,GACETA!$A$1:$C$186,3,0) -> L | G9: Mediación, conciliación y función calificadora municipal | H9: =CONCATENATE(A9," ",C9," ",E9," ",F9) -> D00 108 0103090301 L | I9: Garantizar la paz social, convivencia familiar y vecinal a través de medios alternativos de solucion de controversias.
A10: D00 | B10: SECRETARÍA DEL AYUNTAMIENTO | C10: 108 | D10: Juzgados Cívicos | E10: 0103090301 | F10: =VLOOKUP(E10,GACETA!$A$1:$C$186,3,0) -> L | G10: Mediación, conciliación y función calificadora municipal | H10: =CONCATENATE(A10," ",C10," ",E10," ",F10) -> D00 108 0103090301 L | I10: Citar a las partes en conflicto con la finalidad de dirimir sus diferencias a través del dialogo y medios alternativos de solución
A11: D00 | B11: SECRETARÍA DEL AYUNTAMIENTO | C11: 108 | D11: Juzgados Cívicos | E11: 0103090301 | F11: =VLOOKUP(E11,GACETA!$A$1:$C$186,3,0) -> L | G11: Mediación, conciliación y función calificadora municipal | H11: =CONCATENATE(A11," ",C11," ",E11," ",F11) -> D00 108 0103090301 L | I11: Dar cumplimiento a los ordenamientos legales a través de la aplicación de sanciones por infracciones
A12: D00 | B12: SECRETARÍA DEL AYUNTAMIENTO | C12: 108 | D12: Juzgados Cívicos | E12: 0103090301 | F12: =VLOOKUP(E12,GACETA!$A$1:$C$186,3,0) -> L | G12: Mediación, conciliación y función calificadora municipal | H12: =CONCATENATE(A12," ",C12," ",E12," ",F12) -> D00 108 0103090301 L | I12: Capacitaciones en tematicas relacionadas a la Justicia Civica
A13: D00 | B13: SECRETARÍA DEL AYUNTAMIENTO | C13: 108 | D13: Juzgados Cívicos | E13: 0103090301 | F13: =VLOOKUP(E13,GACETA!$A$1:$C$186,3,0) -> L | G13: Mediación, conciliación y función calificadora municipal | H13: =CONCATENATE(A13," ",C13," ",E13," ",F13) -> D00 108 0103090301 L | I13: Difusión de la cultura civica y cultura de la legalidad en medios de comunicación
A14: D00 | B14: SECRETARÍA DEL AYUNTAMIENTO | C14: 108 | D14: Juzgados Cívicos | E14: 0103090301 | F14: =VLOOKUP(E14,GACETA!$A$1:$C$186,3,0) -> L | G14: Mediación, conciliación y función calificadora municipal | H14: =CONCATENATE(A14," ",C14," ",E14," ",F14) -> D00 108 0103090301 L | I14: Informes de Resultados de las Acciones del Juzgado Cívico
A15: D00 | B15: SECRETARÍA DEL AYUNTAMIENTO | C15: 108 | D15: Juzgados Cívicos | E15: 0103090301 | F15: =VLOOKUP(E15,GACETA!$A$1:$C$186,3,0) -> L | G15: Mediación, conciliación y función calificadora municipal | H15: =CONCATENATE(A15," ",C15," ",E15," ",F15) -> D00 108 0103090301 L | I15: Jornadas de Trabajo en favor de la comunidad
A16: D00 | B16: SECRETARÍA DEL AYUNTAMIENTO | C16: 108 | D16: Juzgados Cívicos | E16: 0103090301 | F16: =VLOOKUP(E16,GACETA!$A$1:$C$186,3,0) -> L | G16: Mediación, conciliación y función calificadora municipal | H16: =CONCATENATE(A16," ",C16," ",E16," ",F16) -> D00 108 0103090301 L | I16: Proporcionar asesorias psicologicas y preventivas escolares, enfocado a pdres y adolecentes
A17: D00 | B17: SECRETARÍA DEL AYUNTAMIENTO | C17: 108 | D17: Juzgados Cívicos | E17: 0103090301 | F17: =VLOOKUP(E17,GACETA!$A$1:$C$186,3,0) -> L | G17: Mediación, conciliación y función calificadora municipal | H17: =CONCATENATE(A17," ",C17," ",E17," ",F17) -> D00 108 0103090301 L | I17: Realizar talleres para jovenes menores infractores para su readapatcion
... A89: L00 | B89: TESORERÍA | C89: 116 | D89: Egresos | E89: 0402010104 | F89: =VLOOKUP(E89,GACETA!$A$1:$C$186,3,0) -> O | G89: Transferencias del ayuntamiento a organismos municipales | H89: =CONCATENATE(A89," ",C89," ",E89," ",F89) -> L00 116 0402010104 O | I89: Transferencia a Organismos Descentralizados
A90: L00 | B90: TESORERÍA | C90: 116 | D90: Egresos | E90: 0404010101 | F90: H | G90: Pasivos derivados de erogaciones devengadas y pendientes de ejercicios anteriores | H90: =CONCATENATE(A90," ",C90," ",E90," ",F90) -> L00 116 0404010101 H | I90: Pago de las ADEFAS del ejercicio
A91: L00 | B91: TESORERÍA | C91: 155 | D91: Área Jurídica | E91: 0103050104 | F91: =VLOOKUP(E91,GACETA!$A$1:$C$186,3,0) -> L | G91: Asesoría jurídica al ayuntamiento | H91: =CONCATENATE(A91," ",C91," ",E91," ",F91) -> L00 155 0103050104 L | I91: Dar cumplimiento a lo ordenado en las sentencias emitidas por los tribunales
A92: L00 | B92: TESORERÍA | C92: 155 | D92: Área Jurídica | E92: 0103050104 | F92: =VLOOKUP(E92,GACETA!$A$1:$C$186,3,0) -> L | G92: Asesoría jurídica al ayuntamiento | H92: =CONCATENATE(A92," ",C92," ",E92," ",F92) -> L00 155 0103050104 L | I92: Contestación de demandas
A93: L00 | B93: TESORERÍA | C93: 155 | D93: Área Jurídica | E93: 0103050104 | F93: =VLOOKUP(E93,GACETA!$A$1:$C$186,3,0) -> L | G93: Asesoría jurídica al ayuntamiento | H93: =CONCATENATE(A93," ",C93," ",E93," ",F93) -> L00 155 0103050104 L | I93: Desahogos de requerimientos
A94: L00 | B94: TESORERÍA | C94: 155 | D94: Área Jurídica | E94: 0103050104 | F94: =VLOOKUP(E94,GACETA!$A$1:$C$186,3,0) -> L | G94: Asesoría jurídica al ayuntamiento | H94: =CONCATENATE(A94," ",C94," ",E94," ",F94) -> L00 155 0103050104 L | I94: Informes previos y justificados
A95: L00 | B95: TESORERÍA | C95: 155 | D95: Área Jurídica | E95: 0103050104 | F95: =VLOOKUP(E95,GACETA!$A$1:$C$186,3,0) -> L | G95: Asesoría jurídica al ayuntamiento | H95: =CONCATENATE(A95," ",C95," ",E95," ",F95) -> L00 155 0103050104 L | I95: Interposición de demandas de amparo
A96: L00 | B96: TESORERÍA | C96: 155 | D96: Área Jurídica | E96: 0103050104 | F96: =VLOOKUP(E96,GACETA!$A$1:$C$186,3,0) -> L | G96: Asesoría jurídica al ayuntamiento | H96: =CONCATENATE(A96," ",C96," ",E96," ",F96) -> L00 155 0103050104 L | I96: Interposición de recursos de revisión y de revocación
A97: L00 | B97: TESORERÍA | C97: 155 | D97: Área Jurídica | E97: 0103050104 | F97: =VLOOKUP(E97,GACETA!$A$1:$C$186,3,0) -> L | G97: Asesoría jurídica al ayuntamiento | H97: =CONCATENATE(A97," ",C97," ",E97," ",F97) -> L00 155 0103050104 L | I97: Oficios de contestación a diversas unidades administrativas
A98: L00 | B98: TESORERÍA | C98: 118 | D98: Catastro Municipal | E98: 0108010201 | F98: =VLOOKUP(E98,GACETA!$A$1:$C$186,3,0) -> E | G98: Servicios e información catastral estatal y municipal | H98: =CONCATENATE(A98," ",C98," ",E98," ",F98) -> L00 118 0108010201 E | I98: Realizar la recepción de solicitudes de trámite catastral
A99: L00 | B99: TESORERÍA | C99: 118 | D99: Catastro Municipal | E99: 0108010201 | F99: =VLOOKUP(E99,GACETA!$A$1:$C$186,3,0) -> E | G99: Servicios e información catastral estatal y municipal | H99: =CONCATENATE(A99," ",C99," ",E99," ",F99) -> L00 118 0108010201 E | I99: Realizar diligencias de inspección y medición física de los predios
A100: L00 | B100: TESORERÍA | C100: 118 | D100: Catastro Municipal | E100: 0108010201 | F100: =VLOOKUP(E100,GACETA!$A$1:$C$186,3,0) -> E | G100: Servicios e información catastral estatal y municipal | H100: =CONCATENATE(A100," ",C100," ",E100," ",F100) -> L00 118 0108010201 E | I100: Verificar los linderos de inmuebles realizados
A101: L00 | B101: TESORERÍA | C101: 118 | D101: Catastro Municipal | E101: 0108010201 | F101: =VLOOKUP(E101,GACETA!$A$1:$C$186,3,0) -> E | G101: Servicios e información catastral estatal y municipal | H101: =CONCATENATE(A101," ",C101," ",E101," ",F101) -> L00 118 0108010201 E | I101: verificar la Certificación de clave y valor catastral
A102: L00 | B102: TESORERÍA | C102: 118 | D102: Catastro Municipal | E102: 0108010201 | F102: =VLOOKUP(E102,GACETA!$A$1:$C$186,3,0) -> E | G102: Servicios e información catastral estatal y municipal | H102: =CONCATENATE(A102," ",C102," ",E102," ",F102) -> L00 118 0108010201 E | I102: Certificación de plano manzanero
... A118: K00 | B118: ÓRGANO INTERNO DE CONTROL MUNICIPAL | C118: 139 | D118: Control Social | E118: 0103040102 | F118: =VLOOKUP(E118,GACETA!$A$1:$C$186,3,0) -> P | G118: Participación social en la formulación, seguimiento, control y evaluación | H118: =CONCATENATE(A118," ",C118," ",E118," ",F118) -> K00 139 0103040102 P | I118: Capacitación a integrantes COCICOVIS
A119: K00 | B119: ÓRGANO INTERNO DE CONTROL MUNICIPAL | C119: 136 | D119: Auditoría Administrativa | E119: 0103040201 | F119: O | G119: Prevención, detección, disuasión, sanción y combate a la corrupción | H119: =CONCATENATE(A119," ",C119," ",E119," ",F119) -> K00 136 0103040201 O | I119: Capacitación a servidores públicos en materia de combate a la corrupción.
A120: K00 | B120: ÓRGANO INTERNO DE CONTROL MUNICIPAL | C120: 136 | D120: Auditoría Administrativa | E120: 0103040201 | F120: O | G120: Prevención, detección, disuasión, sanción y combate a la corrupción | H120: =CONCATENATE(A120," ",C120," ",E120," ",F120) -> K00 136 0103040201 O | I120: Campaña de difusión en Materia de Anticorrupción.
A121: K00 | B121: ÓRGANO INTERNO DE CONTROL MUNICIPAL | C121: 136 | D121: Auditoría Administrativa | E121: 0103040201 | F121: O | G121: Prevención, detección, disuasión, sanción y combate a la corrupción | H121: =CONCATENATE(A121," ",C121," ",E121," ",F121) -> K00 136 0103040201 O | I121: Sesiones del Comité Coordinador del Sistema Anticorrupcion Municipal
A122: K00 | B122: ÓRGANO INTERNO DE CONTROL MUNICIPAL | C122: 136 | D122: Auditoría Administrativa | E122: 0103040201 | F122: O | G122: Prevención, detección, disuasión, sanción y combate a la corrupción | H122: =CONCATENATE(A122," ",C122," ",E122," ",F122) -> K00 136 0103040201 O | I122: Atención de denuncias y/o quejas vía telefónica en el Programa Municipal Anticorrupción
A123: K00 | B123: ÓRGANO INTERNO DE CONTROL MUNICIPAL | C123: 138 | D123: Responsabilidad y Situación Patrimonial | E123: 0103040202 | F123: O | G123: Responsabilidades administrativas | H123: =CONCATENATE(A123," ",C123," ",E123," ",F123) -> K00 138 0103040202 O | I123: Elaboración de informes de expedientes en proceso de substanciación
A124: K00 | B124: ÓRGANO INTERNO DE CONTROL MUNICIPAL | C124: 138 | D124: Responsabilidad y Situación Patrimonial | E124: 0103040202 | F124: O | G124: Responsabilidades administrativas | H124: =CONCATENATE(A124," ",C124," ",E124," ",F124) -> K00 138 0103040202 O | I124: Elaboración de informes de expedientes en proceso de resolución
A125: K00 | B125: ÓRGANO INTERNO DE CONTROL MUNICIPAL | C125: 138 | D125: Responsabilidad y Situación Patrimonial | E125: 0103040203 | F125: =VLOOKUP(E125,GACETA!$A$1:$C$186,3,0) -> O | G125: Declaración de situación patrimonial, de interés y constancia de la declaración fiscal de los servidores públicos | H125: =CONCATENATE(A125," ",C125," ",E125," ",F125) -> K00 138 0103040203 O | I125: Vigilar y consultar el padrón de sujetos obligados.
A126: K00 | B126: ÓRGANO INTERNO DE CONTROL MUNICIPAL | C126: 138 | D126: Responsabilidad y Situación Patrimonial | E126: 0103040203 | F126: =VLOOKUP(E126,GACETA!$A$1:$C$186,3,0) -> O | G126: Declaración de situación patrimonial, de interés y constancia de la declaración fiscal de los servidores públicos | H126: =CONCATENATE(A126," ",C126," ",E126," ",F126) -> K00 138 0103040203 O | I126: Vigilar y consultar los movimientos de altas y bajas del sistema Backoffice Decl@raNET
A127: K00 | B127: ÓRGANO INTERNO DE CONTROL MUNICIPAL | C127: 138 | D127: Responsabilidad y Situación Patrimonial | E127: 0103040203 | F127: =VLOOKUP(E127,GACETA!$A$1:$C$186,3,0) -> O | G127: Declaración de situación patrimonial, de interés y constancia de la declaración fiscal de los servidores públicos | H127: =CONCATENATE(A127," ",C127," ",E127," ",F127) -> K00 138 0103040203 O | I127: Seguimiento de la declaración patrimonial y conflicto de intereses por parte de servidores públicos.
...

Sheet ESTRUCTURA 2026
A1: AREA | B1: NOMBRE AREA | C1: AUXILIAR | D1: NOMBRE AUXILIAR | E1: ESTRUCTURA | F1: CONAC | G1: NOMBRE PROYECTO | H1: FULL | I1: OBJETIVO
A2: A00 | B2: PRESIDENCIA | C2: 100 | D2: Secretaría Particular | E2: 0103010101 | F2: P | G2: Relaciones públicas | H2: A00 100 0103010101 P
A3: A02 | B3: Derechos Humanos | C3: 102 | D3: Derechos Humanos | E3: 0102040102 | F3: E | G3: Protección y defensa de los derechos humanos | H3: A02 102 0102040102 E | I3: Asesoría jurídica a ciudadanos por presuntas violaciones a derechos humanos
A4: J00 | B4: GOBIERNO MUNICIPAL | C4: 102 | D4: Derechos Humanos | E4: 0102040102 | F4: E | G4: Protección y defensa de los derechos humanos | H4: J00 102 0102040102 E | I4: Distribuir trípticos a ciudadanos y migrantes con información referente a sus derechos humanos y de relevancia.
A5: A01 | B5: Comunicación Social | C5: 103 | D5: Comunicación Social | E5: 0108030103 | F5: F | G5: Difusión y comunicación institucional | H5: A01 103 0108030103 F | I5: Campañas publicitarias de acciones gubernamentales
A6: Q00 | B6: SEGURIDAD PÚBLICA Y TRÁNSITO | C6: 104 | D6: Seguridad Pública | E6: 0107010101 | F6: E | G6: Operación y vigilancia para la seguridad y prevención del delito | H6: Q00 104 0107010101 E | I6: Dispositivos de Seguridad
A7: T00 | B7: COORDINACIÓN MUNICIPAL DE PROTECCIÓN CIVIL | C7: 105 | D7: Coordinación Municipal de Protección Civil | E7: 0107020101 | F7: E | G7: Mitigación del impacto de fenómenos perturbadores | H7: T00 105 0107020101 E | I7: Valoración de riesgos en edificios públicos y privados, así como en zonas con riesgo geológico.
A8: D00 | B8: SECRETARÍA DEL AYUNTAMIENTO | C8: 108 | D8: Juzgados Cívicos | E8: 0103090301 | F8: L | G8: Mediación, conciliación y función calificadora municipal | H8: D00 108 0103090301 L | I8: Garantizar la paz social, convivencia familiar y vecinal a través de medios alternativos de solucion de controversias.
A9: B01 | B9: Sindicatura I | C9: 110 | D9: Acción Cívica | E9: 0202020102 | F9: M | G9: Apoyo Solidario | H9: B01 110 0202020102 M | I9: Realizar acciones, obras y apoyos en comunidades por medio de atención a la ciudadanía
A10: B02 | B10: Sindicatura II | C10: 110 | D10: Acción Cívica | E10: 0202020102 | F10: M | G10: Apoyo Solidario | H10: B02 110 0202020102 M | I10: Llevar acabo Sesiones de cabildo para abordar temas en benificio de la poblacion
A11: C01 | B11: Regiduría I | C11: 110 | D11: Acción Cívica | E11: 0202020102 | F11: M | G11: Apoyo Solidario | H11: C01 110 0202020102 M | I11: Realizar acciones, obras y apoyos en comunidades por medio de atención a la ciudadanía
A12: C02 | B12: Regiduría II | C12: 110 | D12: Acción Cívica | E12: 0202020102 | F12: M | G12: Apoyo Solidario | H12: C02 110 0202020102 M | I12: Realizar acciones, obras y apoyos en comunidades por medio de atención a la ciudadanía
A13: C03 | B13: Regiduría III | C13: 110 | D13: Acción Cívica | E13: 0202020102 | F13: M | G13: Apoyo Solidario | H13: C03 110 0202020102 M | I13: Realizar acciones, obras y apoyos en comunidades por medio de atención a la ciudadanía
A14: C04 | B14: Regiduría IV | C14: 110 | D14: Acción Cívica | E14: 0202020102 | F14: M | G14: Apoyo Solidario | H14: C04 110 0202020102 M | I14: Realizar acciones, obras y apoyos en comunidades por medio de atención a la ciudadanía
... A27: F00 | B27: DIRECCIÓN DE DESARROLLO URBANO | C27: 123 | D27: Desarrollo Urbano | E27: 0103080104 | F27: P | G27: Planeación integral y concertada | H27: F00 123 0103080104 P | I27: Elaboración de Plan Municipal de Desarrolllo Urbano
A28: X00 | B28: DIRECCIÓN DE OBRAS PÚBLICAS | C28: 124 | D28: Obras Públicas | E28: 0105020511 | F28: O | G28: Registro, control contable-presupuestal y cuenta de la hacienda pública municipal | H28: X00 124 0105020511 O
A29: H00 | B29: SERVICIOS PÚBLICOS | C29: 125 | D29: Servicios Públicos | E29: 0201010101 | F29: V | G29: Manejo integral de residuos sólidos | H29: H00 125 0201010101 V
A30: I02 | B30: Salud | C30: 129 | D30: Control Antirrábico y Bienestar Animal | E30: 0201050201 | F30: E | G30: Concientización y canalización Animal | H30: I02 129 0201050201 E | I30: Jornada de adopción de canino y/o felino
A31: N00 | B31: DIRECCIÓN DE DESARROLLO ECONÓMICO | C31: 131 | D31: Fomento Industrial | E31: 0304020102 | F31: F | G31: Fortalecimiento a la micro y pequeña empresa | H31: N00 131 0304020102 F | I31: Solicitudes de Licencia de funcionamiento
A32: K00 | B32: ÓRGANO INTERNO DE CONTROL MUNICIPAL | C32: 134 | D32: Auditoría Financiera | E32: 0103040101 | F32: O | G32: Fiscalización, control y evaluación interna de la gestión pública | H32: K00 134 0103040101 O | I32: Atención a las recomendaciones o pliego de observaciones de auditorías externas
A33: O00 | B33: EDUCACIÓN CULTURAL Y BIENESTAR SOCIAL | C33: 141 | D33: Educación | E33: 0205010110 | F33: S | G33: Apoyo municipal a la educación básica | H33: O00 141 0205010110 S | I33: Ejecución de programas para contribuir a mejorar el desarrollo integral de la comunidad estudiantil de Educación básica
A34: I00 | B34: PROMOCIÓN SOCIAL | C34: 143 | D34: Atención a la Juventud | E34: 0206080602 | F34: E | G34: Promoción del bienestar adolescente y juvenil | H34: I00 143 0206080602 E | I34: Prevención de la Violencia
A35: V00 | B35: DIRECCIÓN DE LAS MUJERES | C35: 152 | D35: Atención a la Mujer | E35: 0206080501 | F35: E | G35: Coordinación Institucional para la igualdad de género | H35: V00 152 0206080501 E | I35: Talleres de capacitación en igualdad de género a servidores públicos
A36: F01 | B36: Desarrollo Urbano y Servicios Públicos | C36: 154 | D36: Vialidad y Transporte | E36: 0105020602 | F36: M | G36: Capacitación y profesionalización para el desarrollo del personal | H36: F01 154 0105020602 M | I36: Se brindan las herramientas al personal mediante programas de capacitación técnica, operativa y de educación vial.
A37: G00 | B37: DIRECCIÓN DE ECOLOGÍA | C37: 160 | D37: Prevención y Control Ambiental | E37: 0201040109 | F37: V | G37: Concertación y participación ciudadana para la protección del ambiente | H37: G00 160 0201040109 V | I37: Emisión de permisos, contancias y licencias en pro del mejoramiento ambienta

Sheet dgeneral
A1: id | B1: clave | C1: dependencia
B2: A00 | C2: PRESIDENCIA
B3: A01 | C3: Comunicación Social
B4: A02 | C4: Derechos Humanos
B5: B01 | C5: Sindicatura I
B6: B02 | C6: Sindicatura II
B7: C01 | C7: Regiduría I
B8: C02 | C8: Regiduría II
B9: C03 | C9: Regiduría III
B10: C04 | C10: Regiduría IV
B11: C05 | C11: Regiduría V
B12: C06 | C12: Regiduría VI
B13: C07 | C13: Regiduría VII
... B37: X00 | C37: DIRECCIÓN DE OBRAS PÚBLICAS

Sheet dauxiliar
A1: id | B1: clave | C1: dependencia
B2: 100 | C2: Secretaría Particular
B3: 101 | C3: Secretaría Técnica
B4: 102 | C4: Derechos Humanos
B5: 103 | C5: Comunicación Social
B6: 104 | C6: Seguridad Pública
B7: 105 | C7: Coordinación Municipal de Protección Civil
B8: 106 | C8: Cuerpo de Bomberos
B9: 108 | C9: Juzgados Cívicos
B10: 109 | C10: Registro Civil
B11: 110 | C11: Acción Cívica
B12: 111 | C12: Coordinación de Delegaciones
B13: 112 | C13: Participación Ciudadana
... B54: 172 | C54: Atención a la Población de la Diversidad Sexual

Sheet proyectos
A1: id | B1: clave | C1: conac | D1: descripcion
B2: 0102040102 | C2: E | D2: Protección y defensa de los derechos humanos
B3: 0102040103 | C3: E | D3: Desarrollo institucional para los derechos humanos
B4: 0103010101 | C4: P | D4: Relaciones públicas
B5: 0103010103 | C5: E | D5: Audiencia pública y consulta popular
B6: 0103020104 | C6: E | D6: Capacitación para el desarrollo de la cultura política
B7: 0103030101 | C7: E | D7: Conservación, restauración y difusión del patrimonio cultural
B8: 0103040101 | C8: O | D8: Fiscalización, control y evaluación interna de la gestión pública
B9: 0103040102 | C9: P | D9: Participación social en la formulación, seguimiento, control y evaluación
B10: 0103040201 | C10: O | D10: Prevención, detección, disuasión, sanción y combate a la corrupción
B11: 0103040202 | C11: O | D11: Responsabilidades administrativas
B12: 0103040203 | C12: O | D12: Declaración de situación patrimonial, de interés y constancia de la declaración fiscal de los servidores públicos
B13: 0103040205 | C13: O | D13: Investigación de faltas administrativas
... B268: 0404010101 | C268: H | D268: Pasivos derivados de erogaciones devengadas y pendientes de ejercicios anteriores

Sheet Objetivo
A1: ÁREA ADMINISTRATIVA | B1: Denominación de Programa | C1: Denominación de Proyecto | D1: Obejetivo | E1: Propuesta de Objetivo para el PDM 2025 | F1: Descripción de Acciones
A2: SECRETARÍA DEL AYUNTAMIENTO | B2: Reglamentación municipal | C2: Revisión y emisión de la reglamentación municipal | D2: Incluye todos los procesos necesarios para que los ayuntamientos desarrollen los trabajos para creación, rediseño, actualización, publicación y difusión de la reglamentación municipal. | F2: Reglamentos y disposiciones de observancia general en el municipio publicadas | I2: Metas
F3: Capacitaciones en materia reglamentaria otorgadas | I3: Qué podemos aprovechar
F4: Revisión de propuestas viables de modificación a Leyes, decretos y reglamentos municipales | I4: Qué temas podemos atender
F5: Realización de sesiones de cabildo
B6: Consolidación de la administración pública para resultados | C6: Control del patrimonio y normatividad | D6: Comprende el conjunto de actividades y herramientas para coadyuvar a que la actuación de los servidores públicos sea eficaz, eficiente y transparente, a fin de generar resultados con apego a los principios de legalidad, objetividad, profesionalismo, honradez, lealtad, imparcialidad, eficiencia, eficacia, equidad, transparencia, economía, integridad, que permiten la toma de decisiones sobre la aplicación de los recursos públicos con el objeto de mejorar la calidad del gasto público y la rendición de cuentas. | F6: Realizar los levantamientos fisicos de los bienes muebles e inmuebles.
F7: Actualizar el inventario mediante revisiones fisicas por areas de trabajo de la Administracion Publica Municipal.
F8: Digitalización de documentación oficial por área,
B9: Justicia civica municipal | C9: Mediación, conciliación y función calificadora municipal | D9: Se orienta al cumplimiento de las atribuciones municipales contenidas en la Ley de Justicia Cívica del Estado de México y Municipios, así como la Ley de Mediación, Conciliación y Promoción de la Paz Social para el Estado de México, vigentes | F9: Garantizar la paz social, convivencia familiar y vecinal a través de medios alternativos de solucion de controversias.
F10: Citar a las partes en conflicto con la finalidad de dirimir sus diferencias a través del dialogo y medios alternativos de solución
F11: Dar cumplimiento a los ordenamientos legales a través de la aplicación de sanciones por infracciones
F12: Capacitaciones en tematicas relacionadas a la Justicia Civica
F13: Difusión de la cultura civica y cultura de la legalidad en medios de comunicación
F14: Informes de Resultados de las Acciones del Juzgado Cívico
F15: Jornadas de Trabajo en favor de la comunidad
B16: Protección jurídica de las personas | C16: Actualizacion y operación del registro civil | D16: Conjunto de acciones para el fortalecimiento de la certeza jurídica, edificando una alianza entre los distintos órdenes de gobierno y la población, a fin de consolidar una cultura de legalidad que impacte en la prevención del delito. | F16: Emitir copias certificadas de actas en las oficialías del Registro Civil aprovechando el uso de las tecnologías.
F17: Proporcionar las constancias de no registro de una forma más ágil a los solicitantes
F18: Supervisiones a las Oficialías del Registro Civil
F19: Incrementar el número de parejas que regularizan su estado civil mediante campañas de matrimonios masivos.
F20: Incrementar el número de parejas que regularicen su estatus jurídico y personalidad mediante campañas de registros extemporáneos
F21: Eventos de Matrimonios Masivos
A22: Sindicatura I | B22: Conducción de las políticas generales de gobierno | C22: Audiencia Pública y consulta popular | D22: Ejercer un gobierno democrático que impulse la participación social y ofrezca servicio de calidad en el marco de legalidad y justicia, para elevar las condiciones de vida en la población | F22: Fortalecer el marco normativo del ayuntamiento
F23: Divulgación de las políticas públicas municipales en los medios de comunicación institucional
A24: Sindicatura II | B24: Conducción de las políticas generales de gobierno | C24: Audiencia Pública y consulta popular | D24: Ejercer un gobierno democrático que impulse la participación social y ofrezca servicio de calidad en el marco de legalidad y justicia, para elevar las condiciones de vida en la población | F24: Fortalecer el marco normativo del ayuntamiento
F25: Divulgación de las políticas públicas municipales en los medios de comunicación institucional
A26: REGIDURÍA I | B26: Conducción de las políticas generales de gobierno | C26: Audiencia Pública y consulta popular | D26: Ejercer un gobierno democrático que impulse la participación social y ofrezca servicio de calidad en el marco de legalidad y justicia, para elevar las condiciones de vida en la población | F26: Fortalecer el marco normativo del ayuntamiento
F27: Divulgación de las políticas públicas municipales en los medios de comunicación institucional
A28: REGIDURÍA II | B28: Conducción de las políticas generales de gobierno | C28: Audiencia Pública y consulta popular | D28: Ejercer un gobierno democrático que impulse la participación social y ofrezca servicio de calidad en el marco de legalidad y justicia, para elevar las condiciones de vida en la población | F28: Fortalecer el marco normativo del ayuntamiento
F29: Divulgación de las políticas públicas municipales en los medios de comunicación institucional
A30: REGIDURÍA III | B30: Conducción de las políticas generales de gobierno | C30: Audiencia Pública y consulta popular | D30: Ejercer un gobierno democrático que impulse la participación social y ofrezca servicio de calidad en el marco de legalidad y justicia, para elevar las condiciones de vida en la población | F30: Fortalecer el marco normativo del ayuntamiento
F31: Divulgación de las políticas públicas municipales en los medios de comunicación institucional
A32: REGIDURÍA IV | B32: Conducción de las políticas generales de gobierno | C32: Audiencia Pública y consulta popular | D32: Ejercer un gobierno democrático que impulse la participación social y ofrezca servicio de calidad en el marco de legalidad y justicia, para elevar las condiciones de vida en la población | F32: Fortalecer el marco normativo del ayuntamiento
F33: Divulgación de las políticas públicas municipales en los medios de comunicación institucional
A34: REGIDURÍA V | B34: Conducción de las políticas generales de gobierno | C34: Audiencia Pública y consulta popular | D34: Ejercer un gobierno democrático que impulse la participación social y ofrezca servicio de calidad en el marco de legalidad y justicia, para elevar las condiciones de vida en la población | F34: Fortalecer el marco normativo del ayuntamiento
F35: Divulgación de las políticas públicas municipales en los medios de comunicación institucional
A36: REGIDURÍA VI | B36: Conducción de las políticas generales de gobierno | C36: Audiencia Pública y consulta popular | D36: Ejercer un gobierno democrático que impulse la participación social y ofrezca servicio de calidad en el marco de legalidad y justicia, para elevar las condiciones de vida en la población | F36: Fortalecer el marco normativo del ayuntamiento
F37: Divulgación de las políticas públicas municipales en los medios de comunicación institucional
A38: REGIDURÍA VII | B38: Conducción de las políticas generales de gobierno | C38: Audiencia Pública y consulta popular | D38: Ejercer un gobierno democrático que impulse la participación social y ofrezca servicio de calidad en el marco de legalidad y justicia, para elevar las condiciones de vida en la población | F38: Fortalecer el marco normativo del ayuntamiento
F39: Divulgación de las políticas públicas municipales en los medios de comunicación institucional
A40: REGIDURÍA VIII | B40: Conducción de las políticas generales de gobierno | C40: Audiencia Pública y consulta popular | D40: Ejercer un gobierno democrático que impulse la participación social y ofrezca servicio de calidad en el marco de legalidad y justicia, para elevar las condiciones de vida en la población | F40: Fortalecer el marco normativo del ayuntamiento
...

Sheet Ob, Nuevos
G2: Ecatepec como Modelo de Protección Civil
F7: Estrategias
B8: programa | C8: proyecto
A9: DIRECCIÓN GENERAL DE SEGURIDAD CIUDADANA Y TRÁNSITO MUNICIPAL | B9: Seguridad pública | C9: Operación y vigilancia para la seguridad y prevención del delito | D9: Incluye los proyectos orientados a combatir la inseguridad pública con estricto apego a la ley para erradicar la impunidad y la corrupción, mediante la profesionalización de los cuerpos de seguridad, modificando los métodos y programas de estudio para humanizarlos, dignificarlos y hacerlos más eficientes, aplicando sistemas de reclutamiento y selección confiable y riguroso proceso estandarizado de evaluación, así como promover la participación social en acciones preventivas del delito. | E9: Disminuir la incidencia delictiva, mediante la reestructuración del territorio del municiio como Plan operativo, en el municipio cde Ecatepec. | F9: Disminuir, índice de delitos por medio de la optimización del Modelo Operativo Policial. Territorialidad del Municipio para la proximidad de elementos policiales así como identificar los cuadrantes para ejecutar operativos conjuntos para reducir la generación de violencia y delitos que atenten a la sociedad. | G9: Dispositivos de Seguridad
C10: Tecnología, inteligencia e investigación para la prevención y combate al delito | D10: Incluye los proyectos orientados a combatir la inseguridad pública con estricto apego a la ley para erradicar la impunidad y la corrupción, mediante la profesionalización de los cuerpos de seguridad, modificando los métodos y programas de estudio para humanizarlos, dignificarlos y hacerlos más eficientes, aplicando sistemas de reclutamiento y selección confiable y riguroso proceso estandarizado de evaluación, así como promover la participación social en acciones preventivas del delito. | E10: Fortalecer la inteligencia e investigación, por medio de la explotación y el emleo de las tecnologías de informació y comunicación. | G10: Generación de folios para realizar puestas a disposición ante el Ministerio Público y las oficialías calificadoras-conciliadoras por faltas administrativas.
F11: Con la ayuda de la tenología, inteligencia e investigación | G11: Registro o captura del Informe Policial Homologado puestas a disposición ante el Ministerio Público
F12: Pln de comunicaciones policial | G12: Consulta de los datos generales de las personas y vehículos en el sistema Único de Investigación Criminal (SUIC)
G13: Consulta de los datos generales de las personas y vehículos en el Sistema Único de Investigación Criminal Estatal (SUICE)
G14: Registro de delitos en el Sistema Nacional de detenciones del fuero común y federal.
G15: Registro de delitos en el Sistema Nacional de detenciones de faltas administrativas.
G16: Informe de Incidencia Delictiva para poder determinar e implementar más operativos.
G17: Registro de llamadas de emergencia de la ciudadanía a través del Sistema SafetyNat Cad
G18: Actualización integral del atlas de la incidencia delictiva municipal
G19: Análisis delictivo para la prevención y combate de los delitos de alto impacto
G20: Publicaciones informativas a través de las cuentas oficiales de redes sociales
C21: Formación profresional especializada para personas servidoras públicas de instituciones de seguridad pública | D21: Incluye los proyectos orientados a combatir la inseguridad pública con estricto apego a la ley para erradicar la impunidad y la corrupción, mediante la profesionalización de los cuerpos de seguridad, modificando los métodos y programas de estudio para humanizarlos, dignificarlos y hacerlos más eficientes, aplicando sistemas de reclutamiento y selección confiable y riguroso proceso estandarizado de evaluación, así como promover la participación social en acciones preventivas del delito. | E21: Elevar la percepción de seguridad por medio de programas anticorrupción, de prevención dirigidos a la capacitación de elementos de seguridad y servidores públicos en el municipio. Atender las causa que originan la violencia a través de recuperación de espacios, promoción de ética, valores y sentido de pertenencia, respeto a los derechos humanos, | G21: Capacitación a las fuerzas policiacas en diversos rubros de seguridad pública
F22: Evaluación de los elementos de seguridad para la depuración y reclutamiento | G22: Registro ante el Sistema Nacional de Personal de Seguridad Pública, para la emisión del Certificado Único Policial.
G23: Aplicación de Exámenes de Control de Confianza a personal en activo
G24: Recepción de expedientes derivado de quejas. Tarjetas informativas, redes sociales o denuncias anónimas, encontrar de los elementos que pertenecen a la DSPYT, así como la resolución de los mismos.
G25: Integración y seguimiento a Juicios Administrativos, ante diferentes órganos jurisdiccionales, locales y Federales en contra de la comisión de Honor y justicia de la dirección de Seguridad pública y Transito
C26: Vinculación, participación, prevención del delito y denuncia social | D26: Incluye los proyectos orientados a combatir la inseguridad pública con estricto apego a la ley para erradicar la impunidad y la corrupción, mediante la profesionalización de los cuerpos de seguridad, modificando los métodos y programas de estudio para humanizarlos, dignificarlos y hacerlos más eficientes, aplicando sistemas de reclutamiento y selección confiable y riguroso proceso estandarizado de evaluación, así como promover la participación social en acciones preventivas del delito. | E26: Incrementar la cooordinación con otras instancias de gobierno, con la iniciativa privada y sectores de la sociedad civil con el fin de crear mecanismos de colaboración a favor de la seguridad y la paz. | G26: Atenciones ciudadanas en materia de violencia familiar y de género
G27: Atenciones ciudadanas por extravío o desaparición de personas
G28: Asesoría a mujeres en situaciones de violencia
G29: Actividades culturales y deportivas con la comunidad
C30: Mantenimiento de los dispositivos para el control de transito y educación vial | E30: Implementar acciones específicas para mejorar la gestión de la seguridad vial, / proveer infraestructura segura y con accesibilidad universal, / fomentar el uso de vehículos más seguros / educar a las personas usuarias sobre la importancia de la seguridad vial / mejorar la respuesta posterior a los hechos de tránsito para dar una atención integral a las víctimas directas e indirectas en términos de atención pre-hospitalaria y acceso a la justicia.
B34: Coordinación Intergubernamental para la seguridad publica | C34: Acciones del programa nacional de seguridad pública | D34: Se orienta a la coordinación de acciones que permitan eficientar los mecanismos en materia de seguridad pública con apego a la legalidad que garantice el logro de objetivos gubernamentales. | E34: Eficientar los mecanismos en materia de seguridad pública, para ampliar el alcacnce a la respueta policial y de prevención | G34: Celebración de sesiones del consejo Intermunicipal de Seguridad pública
G35: Sesiones del consejo municipal de seguridad publica
G36: Programa para la adquisicion de implementos basicos para el desarrollo de la funcion policial

Sheet Pp y Py 2026
A1: DG | B1: ÁREA ADMINISTRATIVA | C1: Fin | D1: FN | E1: SF | F1: PG | G1: SP | H1: Py | I1: DG | J1: D Aux | K1: Denominación de Programa | L1: Denominación de Proyecto
A2: D00 | B2: SECRETARÍA DEL AYUNTAMIENTO | C2: 01 | D2: 03 | E2: 09 | F2: 02 | G2: 01 | H2: 01 | I2: D00 | J2: 155 | K2: Reglamentación municipal | L2: Revisión y emisión de la reglamentación municipal
C3: 01 | D3: 05 | E3: 02 | F3: 06 | G3: 06 | I3: D00 | J3: 114 | K3: Consolidación de la administración pública de resultados | L3: Control del patrimonio y normatividad
C4: 01 | D4: 03 | E4: 09 | F4: 03 | G4: 01 | I4: D00 | J4: 108 | K4: Justicia Cívica Municipal | L4: Mediación, conciliación y función calificadora municipal
C5: 01 | D5: 08 | E5: 01 | F5: 01 | G5: 02 | I5: D00 | J5: 109 | K5: Protección Jurídica de las Personas | L5: Actualizacion y operación del Registro Civil | M5: Este faltabaa
A6: B01 | B6: Sindicatura I | C6: 02 | D6: 02 | E6: 02 | F6: 01 | G6: 02 | I6: B01 | J6: 110 | K6: Desarrollo comunitario | L6: Apoyo solidario
A7: B02 | B7: Sindicatura II | C7: 02 | D7: 02 | E7: 02 | F7: 01 | G7: 02 | I7: B02 | J7: 110 | K7: Desarrollo comunitario | L7: Apoyo solidario
A8: C01 | B8: REGIDURÍA I | C8: 02 | D8: 02 | E8: 02 | F8: 01 | G8: 02 | I8: C01 | J8: 110 | K8: Desarrollo comunitario | L8: Apoyo solidario
A9: C02 | B9: REGIDURÍA II | C9: 02 | D9: 02 | E9: 02 | F9: 01 | G9: 02 | I9: C02 | J9: 110 | K9: Desarrollo comunitario | L9: Apoyo solidario
A10: C03 | B10: REGIDURÍA III | C10: 02 | D10: 02 | E10: 02 | F10: 01 | G10: 02 | I10: C03 | J10: 110 | K10: Desarrollo comunitario | L10: Apoyo solidario
A11: C04 | B11: REGIDURÍA IV | C11: 02 | D11: 02 | E11: 02 | F11: 01 | G11: 02 | I11: C04 | J11: 110 | K11: Desarrollo comunitario | L11: Apoyo solidario
A12: C05 | B12: REGIDURÍA V | C12: 02 | D12: 02 | E12: 02 | F12: 01 | G12: 02 | I12: C05 | J12: 110 | K12: Desarrollo comunitario | L12: Apoyo solidario
A13: C06 | B13: REGIDURÍA VI | C13: 02 | D13: 02 | E13: 02 | F13: 01 | G13: 02 | I13: C06 | J13: 110 | K13: Desarrollo comunitario | L13: Apoyo solidario
A14: C07 | B14: REGIDURÍA VII | C14: 02 | D14: 02 | E14: 02 | F14: 01 | G14: 02 | I14: C07 | J14: 110 | K14: Desarrollo comunitario | L14: Apoyo solidario
A15: C08 | B15: REGIDURÍA VIII | C15: 02 | D15: 02 | E15: 02 | F15: 01 | G15: 02 | I15: C08 | J15: 110 | K15: Desarrollo comunitario | L15: Apoyo solidario
A16: C09 | B16: REGIDURÍA IX | C16: 02 | D16: 02 | E16: 02 | F16: 01 | G16: 02 | I16: C09 | J16: 110 | K16: Desarrollo comunitario | L16: Apoyo solidario
A17: C10 | B17: REGIDURÍA X | C17: 02 | D17: 02 | E17: 02 | F17: 01 | G17: 02 | I17: C10 | J17: 110 | K17: Desarrollo comunitario | L17: Apoyo solidario
... A20: L00 | B20: TESORERÍA MUNICIPAL | C20: 01 | D20: 05 | E20: 02 | F20: 02 | G20: 01 | I20: L00 | J20: 115 | K20: Fortalecimiento de los ingresos | L20: Captación y recaudación de ingresos
C21: 01 | D21: 05 | E21: 02 | F21: 02 | G21: 09 | I21: L00 | J21: 115 | L21: Registro y control de caja y tesorería
C22: 01 | D22: 05 | E22: 02 | F22: 03 | G22: 04 | I22: L00 | J22: 119 | K22: Administración del programa de inversión pública | L22: Asignación, registro, seguimiento y control de la inversión pública municipal
C23: 01 | D23: 05 | E23: 02 | F23: 05 | G23: 08 | I23: L00 | J23: 119 | K23: Planeación y presupuesto basado en resultados | L23: Planeación y evaluación para el desarrollo municipal
C24: 01 | D24: 05 | E24: 02 | F24: 05 | G24: 10 | I24: L00 | J24: 117 | L24: Integración, seguimiento y control presupuestal del ayuntamiento
C25: 01 | D25: 05 | E25: 02 | F25: 05 | G25: 11 | I25: L00 | J25: 116 | L25: Registro, control contable-presupuestal y cuenta de la hacienda pública municipal
C26: 04 | D26: 01 | E26: 01 | F26: 01 | G26: 04 | I26: L00 | J26: 116 | K26: Deuda pública | L26: Amortización de la deuda (Capital)
C27: 04 | D27: 01 | E27: 01 | F27: 01 | G27: 05 | I27: L00 | J27: 116 | L27: Costo financiero de la deuda (Intereses)
